<mujoco model="dragonfly_cgs1">
  <compiler angle="radian"/>
  <option timestep="0.0001" gravity="0 0 -981" density="0.00128" viscosity="0.000185" cone="elliptic" noslip_iterations="3"/>
  <default>
    <default class="/"/>
  </default>
  <worldbody>
    <body name="thorax" pos="0 0 0">
      <freejoint name="thorax_root"/>
      <geom name="//unnamed_geom_0" class="/" type="ellipsoid" group="4" size="0.55 0.25 0.4" rgba="1 0.871 0.584 1" density="0.94191"/>
      <camera name="track1" class="/" mode="trackcom" pos="4 5 1.466" quat="0.31246 0.22094 0.5334 0.75434"/>
      <camera name="track2" class="/" mode="trackcom" pos="0 -6 0.6" quat="0.70711 0.70711 0 0"/>
      <camera name="rightsidetrack" class="/" mode="trackcom" pos="0 -6 0.3" xyaxes="1 0 0 0 0 1"/>
      <camera name="back" class="/" mode="track" pos="-6.21 0 4.05" xyaxes="0 -1 0 0.707 0 0.707"/>
      <camera name="righthorizon track" class="/" mode="track" pos="0 -6 -0.39" xyaxes="1 0 0 0 0 1"/>
      <camera name="top" class="/" mode="trackcom" pos="0 0 7.5" xyaxes="0 -1 0 1 0 0"/>
      <camera name="hero" class="/" mode="track" pos="2.71 2.7 -0.1" xyaxes="-0.641 0.767 0 -0.045 -0.037 0.998"/>
      <inertial pos="0 0 0" mass="0.217" diaginertia="0.00965 0.0201 0.0158"/>
      <body name="dorsal_shell" pos="0 0 0.0001">
        <geom name="//unnamed_geom_1" class="/" type="ellipsoid" group="4" size="0.55 0.25 0.4" rgba="0.27 0.33 0.42 1" density="0"/>
      </body>
      <body name="head" pos="0.825 0 0">
        <geom name="//unnamed_geom_2" class="/" type="ellipsoid" group="4" size="0.275 0.275 0.275" rgba="1 0.871 0.584 1" density="0.35586"/>
        <body name="head_shell" pos="0 0 0.0001">
          <geom name="//unnamed_geom_3" class="/" type="ellipsoid" group="4" size="0.275 0.275 0.275" rgba="0.27 0.33 0.42 1" density="0"/>
        </body>
      </body>
      <body name="abdomen" pos="-1.7 0 0">
        <geom name="//unnamed_geom_4" class="/" type="ellipsoid" group="4" size="1.15 0.285 0.285" rgba="1 0.871 0.584 1" density="0.15846"/>
        <inertial pos="0 0 0" mass="0.062" diaginertia="0.0201 0.0174 0.0174"/>
      </body>
      <body name="wingFL_gamma_child" pos="0.28 0.25 0.4">
        <geom name="//unnamed_geom_5" class="/" type="sphere" size="0.001" rgba="0 0 0 0" density="1"/>
        <joint name="wingFL_gamma_hinge" class="/" type="hinge" pos="0 0 0" axis="0 0 1" armature="0.01" damping="10000"/>
        <body name="wingFL_beta_child" pos="0 0 0">
          <geom name="//unnamed_geom_6" class="/" type="sphere" size="0.001" rgba="0 0 0 0" density="1"/>
          <joint name="wingFL_beta_hinge" class="/" type="hinge" pos="0 0 0" axis="0 1 0" armature="0.01" damping="10000"/>
          <body name="wingFL_stroke_child" pos="0 0 0">
            <geom name="//unnamed_geom_7" class="/" type="sphere" size="0.001" rgba="0 0 0 0" density="1"/>
            <joint name="wingFL_stroke_hinge" class="/" type="hinge" pos="0 0 0" axis="0 0 1" armature="0.01" damping="1"/>
            <body name="wingFL_pitch_child" pos="0 0 0">
              <geom name="//unnamed_geom_8" class="/" type="sphere" size="0.001" rgba="0 0 0 0" density="1"/>
              <joint name="wingFL_pitch_hinge" class="/" type="hinge" pos="0 0 0" axis="0 1 0" armature="0.01" damping="1"/>
              <body name="wingFL" pos="-0.24 1.6 0">
                <geom name="//unnamed_geom_9" class="/" type="ellipsoid" group="3" size="0.4 1.6 0.008" rgba="0.278 0.302 1 1" density="0.1632" fluidshape="ellipsoid" fluidcoef="20 5 40 50 4"/>
              </body>
            </body>
          </body>
        </body>
      </body>
      <body name="wingFR_gamma_child" pos="0.28 -0.25 0.4">
        <geom name="//unnamed_geom_10" class="/" type="sphere" size="0.001" rgba="0 0 0 0" density="1"/>
        <joint name="wingFR_gamma_hinge" class="/" type="hinge" pos="0 0 0" axis="0 0 1" armature="0.01" damping="10000"/>
        <body name="wingFR_beta_child" pos="0 0 0">
          <geom name="//unnamed_geom_11" class="/" type="sphere" size="0.001" rgba="0 0 0 0" density="1"/>
          <joint name="wingFR_beta_hinge" class="/" type="hinge" pos="0 0 0" axis="0 1 0" armature="0.01" damping="10000"/>
          <body name="wingFR_stroke_child" pos="0 0 0">
            <geom name="//unnamed_geom_12" class="/" type="sphere" size="0.001" rgba="0 0 0 0" density="1"/>
            <joint name="wingFR_stroke_hinge" class="/" type="hinge" pos="0 0 0" axis="0 0 1" armature="0.01" damping="1"/>
            <body name="wingFR_pitch_child" pos="0 0 0">
              <geom name="//unnamed_geom_13" class="/" type="sphere" size="0.001" rgba="0 0 0 0" density="1"/>
              <joint name="wingFR_pitch_hinge" class="/" type="hinge" pos="0 0 0" axis="0 1 0" armature="0.01" damping="1"/>
              <body name="wingFR" pos="-0.24 -1.6 0">
                <geom name="//unnamed_geom_14" class="/" type="ellipsoid" group="3" size="0.4 1.6 0.008" rgba="1 0.361 0.361 1" density="0.1632" fluidshape="ellipsoid" fluidcoef="20 5 40 50 4"/>
              </body>
            </body>
          </body>
        </body>
      </body>
      <body name="wingBL_gamma_child" pos="-0.315 0.25 0.2">
        <geom name="//unnamed_geom_15" class="/" type="sphere" size="0.001" rgba="0 0 0 0" density="1"/>
        <joint name="wingBL_gamma_hinge" class="/" type="hinge" pos="0 0 0" axis="0 0 1" armature="0.01" damping="10000"/>
        <body name="wingBL_beta_child" pos="0 0 0">
          <geom name="//unnamed_geom_16" class="/" type="sphere" size="0.001" rgba="0 0 0 0" density="1"/>
          <joint name="wingBL_beta_hinge" class="/" type="hinge" pos="0 0 0" axis="0 1 0" armature="0.01" damping="10000"/>
          <body name="wingBL_stroke_child" pos="0 0 0">
            <geom name="//unnamed_geom_17" class="/" type="sphere" size="0.001" rgba="0 0 0 0" density="1"/>
            <joint name="wingBL_stroke_hinge" class="/" type="hinge" pos="0 0 0" axis="0 0 1" armature="0.01" damping="1"/>
            <body name="wingBL_pitch_child" pos="0 0 0">
              <geom name="//unnamed_geom_18" class="/" type="sphere" size="0.001" rgba="0 0 0 0" density="1"/>
              <joint name="wingBL_pitch_hinge" class="/" type="hinge" pos="0 0 0" axis="0 1 0" armature="0.01" damping="1"/>
              <body name="wingBL" pos="-0.5625 1.65 0">
                <geom name="//unnamed_geom_19" class="/" type="ellipsoid" group="3" size="0.5625 1.65 0.00825" rgba="0.278 0.302 1 1" density="0.11848" fluidshape="ellipsoid" fluidcoef="1.75 0.9 3.5 2.5 2.5"/>
              </body>
            </body>
          </body>
        </body>
      </body>
      <body name="wingBR_gamma_child" pos="-0.315 -0.25 0.2">
        <geom name="//unnamed_geom_20" class="/" type="sphere" size="0.001" rgba="0 0 0 0" density="1"/>
        <joint name="wingBR_gamma_hinge" class="/" type="hinge" pos="0 0 0" axis="0 0 1" armature="0.01" damping="10000"/>
        <body name="wingBR_beta_child" pos="0 0 0">
          <geom name="//unnamed_geom_21" class="/" type="sphere" size="0.001" rgba="0 0 0 0" density="1"/>
          <joint name="wingBR_beta_hinge" class="/" type="hinge" pos="0 0 0" axis="0 1 0" armature="0.01" damping="10000"/>
          <body name="wingBR_stroke_child" pos="0 0 0">
            <geom name="//unnamed_geom_22" class="/" type="sphere" size="0.001" rgba="0 0 0 0" density="1"/>
            <joint name="wingBR_stroke_hinge" class="/" type="hinge" pos="0 0 0" axis="0 0 1" armature="0.01" damping="1"/>
            <body name="wingBR_pitch_child" pos="0 0 0">
              <geom name="//unnamed_geom_23" class="/" type="sphere" size="0.001" rgba="0 0 0 0" density="1"/>
              <joint name="wingBR_pitch_hinge" class="/" type="hinge" pos="0 0 0" axis="0 1 0" armature="0.01" damping="1"/>
              <body name="wingBR" pos="-0.5625 -1.65 0">
                <geom name="//unnamed_geom_24" class="/" type="ellipsoid" group="3" size="0.5625 1.65 0.00825" rgba="1 0.361 0.361 1" density="0.10912" fluidshape="ellipsoid" fluidcoef="1.75 0.9 3.5 2.5 2.5"/>
              </body>
            </body>
          </body>
        </body>
      </body>
    </body>
  </worldbody>
  <actuator>
    <position name="wingFL_gamma_act" class="/" joint="wingFL_gamma_hinge" kp="5" kv="5000"/>
    <position name="wingFL_beta_servo" class="/" ctrlrange="0 1.5708" joint="wingFL_beta_hinge" kp="500" kv="50"/>
    <position name="wingFL_stroke_servo" class="/" ctrlrange="-1.5708 1.5708" joint="wingFL_stroke_hinge" kp="10000" kv="17"/>
    <position name="wingFL_pitch_servo" class="/" joint="wingFL_pitch_hinge" kp="10000" kv="17"/>
    <position name="wingFR_gamma_act" class="/" joint="wingFR_gamma_hinge" kp="500" kv="50"/>
    <position name="wingFR_beta_servo" class="/" ctrlrange="0 1.5708" joint="wingFR_beta_hinge" kp="500" kv="50"/>
    <position name="wingFR_stroke_servo" class="/" ctrlrange="-1.5708 1.5708" joint="wingFR_stroke_hinge" kp="10000" kv="17"/>
    <position name="wingFR_pitch_servo" class="/" joint="wingFR_pitch_hinge" kp="10000" kv="17"/>
    <position name="wingBL_gamma_act" class="/" ctrlrange="0 0" joint="wingBL_gamma_hinge" kp="500" kv="50"/>
    <position name="wingBL_beta_servo" class="/" ctrlrange="0 1.5708" joint="wingBL_beta_hinge" kp="500" kv="50"/>
    <position name="wingBL_stroke_servo" class="/" ctrlrange="-1.5708 1.5708" joint="wingBL_stroke_hinge" kp="10000" kv="17"/>
    <position name="wingBL_pitch_servo" class="/" joint="wingBL_pitch_hinge" kp="10000" kv="17"/>
    <position name="wingBR_gamma_act" class="/" ctrlrange="0 0" joint="wingBR_gamma_hinge" kp="500" kv="50"/>
    <position name="wingBR_beta_servo" class="/" ctrlrange="0 1.5708" joint="wingBR_beta_hinge" kp="500" kv="50"/>
    <position name="wingBR_stroke_servo" class="/" ctrlrange="-1.5708 1.5708" joint="wingBR_stroke_hinge" kp="10000" kv="17"/>
    <position name="wingBR_pitch_servo" class="/" joint="wingBR_pitch_hinge" kp="10000" kv="17"/>
  </actuator>
</mujoco>
